INFO:httpx:HTTP Request: POST http://127.0.0.1:11434/api/chat "HTTP/1.1 200 OK"
INFO:httpx:HTTP Request: POST http://127.0.0.1:11434/api/chat "HTTP/1.1 200 OK"
INFO:httpx:HTTP Request: POST http://127.0.0.1:11434/api/chat "HTTP/1.1 200 OK"
INFO:httpx:HTTP Request: POST http://127.0.0.1:11434/api/chat "HTTP/1.1 200 OK"
INFO:httpx:HTTP Request: POST http://127.0.0.1:11434/api/chat "HTTP/1.1 200 OK"
ERROR:discord.client:Ignoring exception in on_message
Traceback (most recent call last):
  File "C:\Users\grace\OneDrive\atom-bot\venv\Lib\site-packages\discord\client.py", line 481, in _run_event
    await coro(*args, **kwargs)
  File "C:\Users\grace\OneDrive\atom-bot\cogs\chat.py", line 25, in on_message
    response = query_ollama(message.content)
  File "C:\Users\grace\OneDrive\atom-bot\ollama_client.py", line 38, in query_ollama
    response = ollama.chat(
        model="llama3",
    ...<10 lines>...
        }
    )
TypeError: Client.chat() got an unexpected keyword argument 'base_url'
INFO:httpx:HTTP Request: POST http://127.0.0.1:11434/api/chat "HTTP/1.1 200 OK"
INFO:httpx:HTTP Request: POST http://127.0.0.1:11434/api/chat "HTTP/1.1 200 OK"
WARNING:discord.gateway:Shard ID None heartbeat blocked for more than 10 seconds.
Loop thread traceback (most recent call last):
  File "C:\Users\grace\OneDrive\atom-bot\bot.py", line 47, in <module>
    bot.run(DISCORD_TOKEN)
  File "C:\Users\grace\OneDrive\atom-bot\venv\Lib\site-packages\discord\client.py", line 906, in run
    asyncio.run(runner())
  File "C:\Users\grace\AppData\Local\Programs\Python\Python313\Lib\asyncio\runners.py", line 194, in run
    return runner.run(main)
  File "C:\Users\grace\AppData\Local\Programs\Python\Python313\Lib\asyncio\runners.py", line 118, in run
    return self._loop.run_until_complete(task)
  File "C:\Users\grace\AppData\Local\Programs\Python\Python313\Lib\asyncio\base_events.py", line 707, in run_until_complete
    self.run_forever()
  File "C:\Users\grace\AppData\Local\Programs\Python\Python313\Lib\asyncio\base_events.py", line 678, in run_forever
    self._run_once()
  File "C:\Users\grace\AppData\Local\Programs\Python\Python313\Lib\asyncio\base_events.py", line 2033, in _run_once
    handle._run()
  File "C:\Users\grace\AppData\Local\Programs\Python\Python313\Lib\asyncio\events.py", line 89, in _run
    self._context.run(self._callback, *self._args)
  File "C:\Users\grace\OneDrive\atom-bot\venv\Lib\site-packages\discord\client.py", line 481, in _run_event
    await coro(*args, **kwargs)
  File "C:\Users\grace\OneDrive\atom-bot\cogs\chat.py", line 25, in on_message
    response = query_ollama(message.content)
  File "C:\Users\grace\OneDrive\atom-bot\ollama_client.py", line 43, in query_ollama
    response = ollama.chat(
  File "C:\Users\grace\OneDrive\atom-bot\venv\Lib\site-packages\ollama\_client.py", line 342, in chat
    return self._request(
  File "C:\Users\grace\OneDrive\atom-bot\venv\Lib\site-packages\ollama\_client.py", line 180, in _request
    return cls(**self._request_raw(*args, **kwargs).json())
  File "C:\Users\grace\OneDrive\atom-bot\venv\Lib\site-packages\ollama\_client.py", line 120, in _request_raw
    r = self._client.request(*args, **kwargs)
  File "C:\Users\grace\OneDrive\atom-bot\venv\Lib\site-packages\httpx\_client.py", line 825, in request
    return self.send(request, auth=auth, follow_redirects=follow_redirects)
  File "C:\Users\grace\OneDrive\atom-bot\venv\Lib\site-packages\httpx\_client.py", line 914, in send
    response = self._send_handling_auth(
  File "C:\Users\grace\OneDrive\atom-bot\venv\Lib\site-packages\httpx\_client.py", line 942, in _send_handling_auth
    response = self._send_handling_redirects(
  File "C:\Users\grace\OneDrive\atom-bot\venv\Lib\site-packages\httpx\_client.py", line 979, in _send_handling_redirects
    response = self._send_single_request(request)
  File "C:\Users\grace\OneDrive\atom-bot\venv\Lib\site-packages\httpx\_client.py", line 1014, in _send_single_request
    response = transport.handle_request(request)
  File "C:\Users\grace\OneDrive\atom-bot\venv\Lib\site-packages\httpx\_transports\default.py", line 250, in handle_request
    resp = self._pool.handle_request(req)
  File "C:\Users\grace\OneDrive\atom-bot\venv\Lib\site-packages\httpcore\_sync\connection_pool.py", line 236, in handle_request
    response = connection.handle_request(
  File "C:\Users\grace\OneDrive\atom-bot\venv\Lib\site-packages\httpcore\_sync\connection.py", line 103, in handle_request
    return self._connection.handle_request(request)
  File "C:\Users\grace\OneDrive\atom-bot\venv\Lib\site-packages\httpcore\_sync\http11.py", line 106, in handle_request
    ) = self._receive_response_headers(**kwargs)
  File "C:\Users\grace\OneDrive\atom-bot\venv\Lib\site-packages\httpcore\_sync\http11.py", line 177, in _receive_response_headers
    event = self._receive_event(timeout=timeout)
  File "C:\Users\grace\OneDrive\atom-bot\venv\Lib\site-packages\httpcore\_sync\http11.py", line 217, in _receive_event
    data = self._network_stream.read(
  File "C:\Users\grace\OneDrive\atom-bot\venv\Lib\site-packages\httpcore\_backends\sync.py", line 128, in read
    return self._sock.recv(max_bytes)

WARNING:discord.gateway:Shard ID None heartbeat blocked for more than 20 seconds.
Loop thread traceback (most recent call last):
  File "C:\Users\grace\OneDrive\atom-bot\bot.py", line 47, in <module>
    bot.run(DISCORD_TOKEN)
  File "C:\Users\grace\OneDrive\atom-bot\venv\Lib\site-packages\discord\client.py", line 906, in run
    asyncio.run(runner())
  File "C:\Users\grace\AppData\Local\Programs\Python\Python313\Lib\asyncio\runners.py", line 194, in run
    return runner.run(main)
  File "C:\Users\grace\AppData\Local\Programs\Python\Python313\Lib\asyncio\runners.py", line 118, in run
    return self._loop.run_until_complete(task)
  File "C:\Users\grace\AppData\Local\Programs\Python\Python313\Lib\asyncio\base_events.py", line 707, in run_until_complete
    self.run_forever()
  File "C:\Users\grace\AppData\Local\Programs\Python\Python313\Lib\asyncio\base_events.py", line 678, in run_forever
    self._run_once()
  File "C:\Users\grace\AppData\Local\Programs\Python\Python313\Lib\asyncio\base_events.py", line 2033, in _run_once
    handle._run()
  File "C:\Users\grace\AppData\Local\Programs\Python\Python313\Lib\asyncio\events.py", line 89, in _run
    self._context.run(self._callback, *self._args)
  File "C:\Users\grace\OneDrive\atom-bot\venv\Lib\site-packages\discord\client.py", line 481, in _run_event
    await coro(*args, **kwargs)
  File "C:\Users\grace\OneDrive\atom-bot\cogs\chat.py", line 25, in on_message
    response = query_ollama(message.content)
  File "C:\Users\grace\OneDrive\atom-bot\ollama_client.py", line 43, in query_ollama
    response = ollama.chat(
  File "C:\Users\grace\OneDrive\atom-bot\venv\Lib\site-packages\ollama\_client.py", line 342, in chat
    return self._request(
  File "C:\Users\grace\OneDrive\atom-bot\venv\Lib\site-packages\ollama\_client.py", line 180, in _request
    return cls(**self._request_raw(*args, **kwargs).json())
  File "C:\Users\grace\OneDrive\atom-bot\venv\Lib\site-packages\ollama\_client.py", line 120, in _request_raw
    r = self._client.request(*args, **kwargs)
  File "C:\Users\grace\OneDrive\atom-bot\venv\Lib\site-packages\httpx\_client.py", line 825, in request
    return self.send(request, auth=auth, follow_redirects=follow_redirects)
  File "C:\Users\grace\OneDrive\atom-bot\venv\Lib\site-packages\httpx\_client.py", line 914, in send
    response = self._send_handling_auth(
  File "C:\Users\grace\OneDrive\atom-bot\venv\Lib\site-packages\httpx\_client.py", line 942, in _send_handling_auth
    response = self._send_handling_redirects(
  File "C:\Users\grace\OneDrive\atom-bot\venv\Lib\site-packages\httpx\_client.py", line 979, in _send_handling_redirects
    response = self._send_single_request(request)
  File "C:\Users\grace\OneDrive\atom-bot\venv\Lib\site-packages\httpx\_client.py", line 1014, in _send_single_request
    response = transport.handle_request(request)
  File "C:\Users\grace\OneDrive\atom-bot\venv\Lib\site-packages\httpx\_transports\default.py", line 250, in handle_request
    resp = self._pool.handle_request(req)
  File "C:\Users\grace\OneDrive\atom-bot\venv\Lib\site-packages\httpcore\_sync\connection_pool.py", line 236, in handle_request
    response = connection.handle_request(
  File "C:\Users\grace\OneDrive\atom-bot\venv\Lib\site-packages\httpcore\_sync\connection.py", line 103, in handle_request
    return self._connection.handle_request(request)
  File "C:\Users\grace\OneDrive\atom-bot\venv\Lib\site-packages\httpcore\_sync\http11.py", line 106, in handle_request
    ) = self._receive_response_headers(**kwargs)
  File "C:\Users\grace\OneDrive\atom-bot\venv\Lib\site-packages\httpcore\_sync\http11.py", line 177, in _receive_response_headers
    event = self._receive_event(timeout=timeout)
  File "C:\Users\grace\OneDrive\atom-bot\venv\Lib\site-packages\httpcore\_sync\http11.py", line 217, in _receive_event
    data = self._network_stream.read(
  File "C:\Users\grace\OneDrive\atom-bot\venv\Lib\site-packages\httpcore\_backends\sync.py", line 128, in read
    return self._sock.recv(max_bytes)

WARNING:discord.gateway:Shard ID None heartbeat blocked for more than 30 seconds.
Loop thread traceback (most recent call last):
  File "C:\Users\grace\OneDrive\atom-bot\bot.py", line 47, in <module>
    bot.run(DISCORD_TOKEN)
  File "C:\Users\grace\OneDrive\atom-bot\venv\Lib\site-packages\discord\client.py", line 906, in run
    asyncio.run(runner())
  File "C:\Users\grace\AppData\Local\Programs\Python\Python313\Lib\asyncio\runners.py", line 194, in run
    return runner.run(main)
  File "C:\Users\grace\AppData\Local\Programs\Python\Python313\Lib\asyncio\runners.py", line 118, in run
    return self._loop.run_until_complete(task)
  File "C:\Users\grace\AppData\Local\Programs\Python\Python313\Lib\asyncio\base_events.py", line 707, in run_until_complete
    self.run_forever()
  File "C:\Users\grace\AppData\Local\Programs\Python\Python313\Lib\asyncio\base_events.py", line 678, in run_forever
    self._run_once()
  File "C:\Users\grace\AppData\Local\Programs\Python\Python313\Lib\asyncio\base_events.py", line 2033, in _run_once
    handle._run()
  File "C:\Users\grace\AppData\Local\Programs\Python\Python313\Lib\asyncio\events.py", line 89, in _run
    self._context.run(self._callback, *self._args)
  File "C:\Users\grace\OneDrive\atom-bot\venv\Lib\site-packages\discord\client.py", line 481, in _run_event
    await coro(*args, **kwargs)
  File "C:\Users\grace\OneDrive\atom-bot\cogs\chat.py", line 25, in on_message
    response = query_ollama(message.content)
  File "C:\Users\grace\OneDrive\atom-bot\ollama_client.py", line 43, in query_ollama
    response = ollama.chat(
  File "C:\Users\grace\OneDrive\atom-bot\venv\Lib\site-packages\ollama\_client.py", line 342, in chat
    return self._request(
  File "C:\Users\grace\OneDrive\atom-bot\venv\Lib\site-packages\ollama\_client.py", line 180, in _request
    return cls(**self._request_raw(*args, **kwargs).json())
  File "C:\Users\grace\OneDrive\atom-bot\venv\Lib\site-packages\ollama\_client.py", line 120, in _request_raw
    r = self._client.request(*args, **kwargs)
  File "C:\Users\grace\OneDrive\atom-bot\venv\Lib\site-packages\httpx\_client.py", line 825, in request
    return self.send(request, auth=auth, follow_redirects=follow_redirects)
  File "C:\Users\grace\OneDrive\atom-bot\venv\Lib\site-packages\httpx\_client.py", line 914, in send
    response = self._send_handling_auth(
  File "C:\Users\grace\OneDrive\atom-bot\venv\Lib\site-packages\httpx\_client.py", line 942, in _send_handling_auth
    response = self._send_handling_redirects(
  File "C:\Users\grace\OneDrive\atom-bot\venv\Lib\site-packages\httpx\_client.py", line 979, in _send_handling_redirects
    response = self._send_single_request(request)
  File "C:\Users\grace\OneDrive\atom-bot\venv\Lib\site-packages\httpx\_client.py", line 1014, in _send_single_request
    response = transport.handle_request(request)
  File "C:\Users\grace\OneDrive\atom-bot\venv\Lib\site-packages\httpx\_transports\default.py", line 250, in handle_request
    resp = self._pool.handle_request(req)
  File "C:\Users\grace\OneDrive\atom-bot\venv\Lib\site-packages\httpcore\_sync\connection_pool.py", line 236, in handle_request
    response = connection.handle_request(
  File "C:\Users\grace\OneDrive\atom-bot\venv\Lib\site-packages\httpcore\_sync\connection.py", line 103, in handle_request
    return self._connection.handle_request(request)
  File "C:\Users\grace\OneDrive\atom-bot\venv\Lib\site-packages\httpcore\_sync\http11.py", line 106, in handle_request
    ) = self._receive_response_headers(**kwargs)
  File "C:\Users\grace\OneDrive\atom-bot\venv\Lib\site-packages\httpcore\_sync\http11.py", line 177, in _receive_response_headers
    event = self._receive_event(timeout=timeout)
  File "C:\Users\grace\OneDrive\atom-bot\venv\Lib\site-packages\httpcore\_sync\http11.py", line 217, in _receive_event
    data = self._network_stream.read(
  File "C:\Users\grace\OneDrive\atom-bot\venv\Lib\site-packages\httpcore\_backends\sync.py", line 128, in read
    return self._sock.recv(max_bytes)

INFO:httpx:HTTP Request: POST http://127.0.0.1:11434/api/chat "HTTP/1.1 200 OK"
ERROR:discord.client:Ignoring exception in on_message
Traceback (most recent call last):
  File "C:\Users\grace\OneDrive\atom-bot\venv\Lib\site-packages\discord\client.py", line 481, in _run_event
    await coro(*args, **kwargs)
  File "C:\Users\grace\OneDrive\atom-bot\cogs\chat.py", line 26, in on_message
    await message.channel.send(response)
  File "C:\Users\grace\OneDrive\atom-bot\venv\Lib\site-packages\discord\abc.py", line 1644, in send
    data = await state.http.send_message(channel.id, params=params)
           ^^^^^^^^^^^^^^^^^^^^^^^^^^^^^^^^^^^^^^^^^^^^^^^^^^^^^^^^
  File "C:\Users\grace\OneDrive\atom-bot\venv\Lib\site-packages\discord\http.py", line 762, in request
    raise HTTPException(response, data)
discord.errors.HTTPException: 400 Bad Request (error code: 50035): Invalid Form Body
In content: Must be 2000 or fewer in length.
INFO:discord.gateway:Shard ID None has successfully RESUMED session e3965297a2c9322ef29cbb24a1d0191a.
INFO:httpx:HTTP Request: POST http://127.0.0.1:11434/api/chat "HTTP/1.1 200 OK"
INFO:httpx:HTTP Request: POST http://127.0.0.1:11434/api/chat "HTTP/1.1 200 OK"
INFO:httpx:HTTP Request: POST http://127.0.0.1:11434/api/chat "HTTP/1.1 200 OK"
INFO:httpx:HTTP Request: POST http://127.0.0.1:11434/api/chat "HTTP/1.1 200 OK"
INFO:httpx:HTTP Request: POST http://127.0.0.1:11434/api/chat "HTTP/1.1 200 OK"
INFO:httpx:HTTP Request: POST http://127.0.0.1:11434/api/chat "HTTP/1.1 200 OK"
INFO:httpx:HTTP Request: POST http://127.0.0.1:11434/api/chat "HTTP/1.1 200 OK"
ERROR:discord.ext.tasks:Unhandled exception in internal background task 'check_reminders'.
Traceback (most recent call last):
  File "C:\Users\grace\OneDrive\atom-bot\venv\Lib\site-packages\discord\ext\tasks\__init__.py", line 246, in _loop
    await self.coro(*args, **kwargs)
  File "C:\Users\grace\OneDrive\atom-bot\cogs\reminders.py", line 45, in check_reminders
    c.execute("SELECT id, user_id, reminder FROM reminders WHERE remind_at <= ?", (datetime.now(),))
    ~~~~~~~~~^^^^^^^^^^^^^^^^^^^^^^^^^^^^^^^^^^^^^^^^^^^^^^^^^^^^^^^^^^^^^^^^^^^^^^^^^^^^^^^^^^^^^^^
sqlite3.OperationalError: no such table: reminders
ERROR:asyncio:Task exception was never retrieved
future: <Task finished name='discord-ext-tasks: Reminders.check_reminders' coro=<Loop._loop() done, defined at C:\Users\grace\OneDrive\atom-bot\venv\Lib\site-packages\discord\ext\tasks\__init__.py:207> exception=OperationalError('no such table: reminders')>
Traceback (most recent call last):
  File "C:\Users\grace\OneDrive\atom-bot\venv\Lib\site-packages\discord\ext\tasks\__init__.py", line 271, in _loop
    raise exc
  File "C:\Users\grace\OneDrive\atom-bot\venv\Lib\site-packages\discord\ext\tasks\__init__.py", line 246, in _loop
    await self.coro(*args, **kwargs)
  File "C:\Users\grace\OneDrive\atom-bot\cogs\reminders.py", line 45, in check_reminders
    c.execute("SELECT id, user_id, reminder FROM reminders WHERE remind_at <= ?", (datetime.now(),))
    ~~~~~~~~~^^^^^^^^^^^^^^^^^^^^^^^^^^^^^^^^^^^^^^^^^^^^^^^^^^^^^^^^^^^^^^^^^^^^^^^^^^^^^^^^^^^^^^^
sqlite3.OperationalError: no such table: reminders
ERROR:discord.ext.commands.bot:Ignoring exception in command None
discord.ext.commands.errors.CommandNotFound: Command "remind" is not found
INFO:httpx:HTTP Request: POST https://8f2c-205-185-98-8.ngrok-free.app/api/chat "HTTP/1.1 200 OK"
ERROR:discord.client:Ignoring exception in on_ready
Traceback (most recent call last):
  File "C:\Users\grace\OneDrive\atom-bot\venv\Lib\site-packages\discord\ext\commands\bot.py", line 963, in _load_from_module_spec
    await setup(self)
  File "C:\Users\grace\OneDrive\atom-bot\cogs\reminders.py", line 66, in setup
    await bot.add_cog(Reminders(bot))
                      ~~~~~~~~~^^^^^
  File "C:\Users\grace\OneDrive\atom-bot\cogs\reminders.py", line 11, in __init__
    self.check_reminders.start()
    ^^^^^^^^^^^^^^^^^^^^
AttributeError: 'Reminders' object has no attribute 'check_reminders'

The above exception was the direct cause of the following exception:

Traceback (most recent call last):
  File "C:\Users\grace\OneDrive\atom-bot\venv\Lib\site-packages\discord\client.py", line 481, in _run_event
    await coro(*args, **kwargs)
  File "C:\Users\grace\OneDrive\atom-bot\bot.py", line 18, in on_ready
    await bot.load_extension(f"cogs.{filename[:-3]}")
  File "C:\Users\grace\OneDrive\atom-bot\venv\Lib\site-packages\discord\ext\commands\bot.py", line 1029, in load_extension
    await self._load_from_module_spec(spec, name)
  File "C:\Users\grace\OneDrive\atom-bot\venv\Lib\site-packages\discord\ext\commands\bot.py", line 968, in _load_from_module_spec
    raise errors.ExtensionFailed(key, e) from e
discord.ext.commands.errors.ExtensionFailed: Extension 'cogs.reminders' raised an error: AttributeError: 'Reminders' object has no attribute 'check_reminders'
ERROR:discord.ext.commands.bot:Ignoring exception in command None
discord.ext.commands.errors.CommandNotFound: Command "tasjs" is not found
INFO:httpx:HTTP Request: POST https://8f2c-205-185-98-8.ngrok-free.app/api/chat "HTTP/1.1 200 OK"
ERROR:discord.ext.commands.bot:Ignoring exception in command deletetask
Traceback (most recent call last):
  File "C:\Users\grace\OneDrive\atom-bot\venv\Lib\site-packages\discord\ext\commands\converter.py", line 1335, in _actual_conversion
    return converter(argument)
ValueError: invalid literal for int() with base 10: 'Go'

The above exception was the direct cause of the following exception:

Traceback (most recent call last):
  File "C:\Users\grace\OneDrive\atom-bot\venv\Lib\site-packages\discord\ext\commands\bot.py", line 1366, in invoke
    await ctx.command.invoke(ctx)
  File "C:\Users\grace\OneDrive\atom-bot\venv\Lib\site-packages\discord\ext\commands\core.py", line 1021, in invoke
    await self.prepare(ctx)
  File "C:\Users\grace\OneDrive\atom-bot\venv\Lib\site-packages\discord\ext\commands\core.py", line 938, in prepare
    await self._parse_arguments(ctx)
  File "C:\Users\grace\OneDrive\atom-bot\venv\Lib\site-packages\discord\ext\commands\core.py", line 845, in _parse_arguments
    transformed = await self.transform(ctx, param, attachments)
                  ^^^^^^^^^^^^^^^^^^^^^^^^^^^^^^^^^^^^^^^^^^^^^
  File "C:\Users\grace\OneDrive\atom-bot\venv\Lib\site-packages\discord\ext\commands\core.py", line 715, in transform
    return await run_converters(ctx, converter, argument, param)  # type: ignore
           ^^^^^^^^^^^^^^^^^^^^^^^^^^^^^^^^^^^^^^^^^^^^^^^^^^^^^
  File "C:\Users\grace\OneDrive\atom-bot\venv\Lib\site-packages\discord\ext\commands\converter.py", line 1444, in run_converters
    return await _actual_conversion(ctx, converter, argument, param)
           ^^^^^^^^^^^^^^^^^^^^^^^^^^^^^^^^^^^^^^^^^^^^^^^^^^^^^^^^^
  File "C:\Users\grace\OneDrive\atom-bot\venv\Lib\site-packages\discord\ext\commands\converter.py", line 1344, in _actual_conversion
    raise BadArgument(f'Converting to "{name}" failed for parameter "{param.name}".') from exc
discord.ext.commands.errors.BadArgument: Converting to "int" failed for parameter "task_id".
ERROR:discord.ext.commands.bot:Ignoring exception in command alert
Traceback (most recent call last):
  File "C:\Users\grace\OneDrive\atom-bot\venv\Lib\site-packages\discord\ext\commands\core.py", line 235, in wrapped
    ret = await coro(*args, **kwargs)
          ^^^^^^^^^^^^^^^^^^^^^^^^^^^
  File "C:\Users\grace\OneDrive\atom-bot\cogs\alerts.py", line 55, in alert
    channel = discord.utils.get(ctx.guild.text_channels, name="alerts")
                                ^^^^^^^^^^^^^^^^^^^^^^^
AttributeError: 'NoneType' object has no attribute 'text_channels'

The above exception was the direct cause of the following exception:

Traceback (most recent call last):
  File "C:\Users\grace\OneDrive\atom-bot\venv\Lib\site-packages\discord\ext\commands\bot.py", line 1366, in invoke
    await ctx.command.invoke(ctx)
  File "C:\Users\grace\OneDrive\atom-bot\venv\Lib\site-packages\discord\ext\commands\core.py", line 1029, in invoke
    await injected(*ctx.args, **ctx.kwargs)  # type: ignore
    ^^^^^^^^^^^^^^^^^^^^^^^^^^^^^^^^^^^^^^^
  File "C:\Users\grace\OneDrive\atom-bot\venv\Lib\site-packages\discord\ext\commands\core.py", line 244, in wrapped
    raise CommandInvokeError(exc) from exc
discord.ext.commands.errors.CommandInvokeError: Command raised an exception: AttributeError: 'NoneType' object has no attribute 'text_channels'
WARNING:discord.gateway:Shard ID None heartbeat blocked for more than 10 seconds.
Loop thread traceback (most recent call last):
  File "C:\Users\grace\OneDrive\atom-bot\bot.py", line 47, in <module>
    bot.run(DISCORD_TOKEN)
  File "C:\Users\grace\OneDrive\atom-bot\venv\Lib\site-packages\discord\client.py", line 906, in run
    asyncio.run(runner())
  File "C:\Users\grace\AppData\Local\Programs\Python\Python313\Lib\asyncio\runners.py", line 194, in run
    return runner.run(main)
  File "C:\Users\grace\AppData\Local\Programs\Python\Python313\Lib\asyncio\runners.py", line 118, in run
    return self._loop.run_until_complete(task)
  File "C:\Users\grace\AppData\Local\Programs\Python\Python313\Lib\asyncio\base_events.py", line 707, in run_until_complete
    self.run_forever()
  File "C:\Users\grace\AppData\Local\Programs\Python\Python313\Lib\asyncio\base_events.py", line 678, in run_forever
    self._run_once()
  File "C:\Users\grace\AppData\Local\Programs\Python\Python313\Lib\asyncio\base_events.py", line 2033, in _run_once
    handle._run()
  File "C:\Users\grace\AppData\Local\Programs\Python\Python313\Lib\asyncio\events.py", line 89, in _run
    self._context.run(self._callback, *self._args)
  File "C:\Users\grace\OneDrive\atom-bot\venv\Lib\site-packages\discord\client.py", line 481, in _run_event
    await coro(*args, **kwargs)
  File "C:\Users\grace\OneDrive\atom-bot\cogs\chat.py", line 28, in on_message
    response = query_ollama(message.content)
  File "C:\Users\grace\OneDrive\atom-bot\ollama_client.py", line 66, in query_ollama
    response = ollama_client.chat(
  File "C:\Users\grace\OneDrive\atom-bot\venv\Lib\site-packages\ollama\_client.py", line 342, in chat
    return self._request(
  File "C:\Users\grace\OneDrive\atom-bot\venv\Lib\site-packages\ollama\_client.py", line 180, in _request
    return cls(**self._request_raw(*args, **kwargs).json())
  File "C:\Users\grace\OneDrive\atom-bot\venv\Lib\site-packages\ollama\_client.py", line 120, in _request_raw
    r = self._client.request(*args, **kwargs)
  File "C:\Users\grace\OneDrive\atom-bot\venv\Lib\site-packages\httpx\_client.py", line 825, in request
    return self.send(request, auth=auth, follow_redirects=follow_redirects)
  File "C:\Users\grace\OneDrive\atom-bot\venv\Lib\site-packages\httpx\_client.py", line 914, in send
    response = self._send_handling_auth(
  File "C:\Users\grace\OneDrive\atom-bot\venv\Lib\site-packages\httpx\_client.py", line 942, in _send_handling_auth
    response = self._send_handling_redirects(
  File "C:\Users\grace\OneDrive\atom-bot\venv\Lib\site-packages\httpx\_client.py", line 979, in _send_handling_redirects
    response = self._send_single_request(request)
  File "C:\Users\grace\OneDrive\atom-bot\venv\Lib\site-packages\httpx\_client.py", line 1014, in _send_single_request
    response = transport.handle_request(request)
  File "C:\Users\grace\OneDrive\atom-bot\venv\Lib\site-packages\httpx\_transports\default.py", line 250, in handle_request
    resp = self._pool.handle_request(req)
  File "C:\Users\grace\OneDrive\atom-bot\venv\Lib\site-packages\httpcore\_sync\connection_pool.py", line 236, in handle_request
    response = connection.handle_request(
  File "C:\Users\grace\OneDrive\atom-bot\venv\Lib\site-packages\httpcore\_sync\connection.py", line 78, in handle_request
    stream = self._connect(request)
  File "C:\Users\grace\OneDrive\atom-bot\venv\Lib\site-packages\httpcore\_sync\connection.py", line 124, in _connect
    stream = self._network_backend.connect_tcp(**kwargs)
  File "C:\Users\grace\OneDrive\atom-bot\venv\Lib\site-packages\httpcore\_backends\sync.py", line 208, in connect_tcp
    sock = socket.create_connection(
  File "C:\Users\grace\AppData\Local\Programs\Python\Python313\Lib\socket.py", line 849, in create_connection
    sock.connect(sa)

ERROR:discord.client:Ignoring exception in on_message
Traceback (most recent call last):
  File "C:\Users\grace\OneDrive\atom-bot\venv\Lib\site-packages\httpx\_transports\default.py", line 101, in map_httpcore_exceptions
    yield
  File "C:\Users\grace\OneDrive\atom-bot\venv\Lib\site-packages\httpx\_transports\default.py", line 250, in handle_request
    resp = self._pool.handle_request(req)
  File "C:\Users\grace\OneDrive\atom-bot\venv\Lib\site-packages\httpcore\_sync\connection_pool.py", line 256, in handle_request
    raise exc from None
  File "C:\Users\grace\OneDrive\atom-bot\venv\Lib\site-packages\httpcore\_sync\connection_pool.py", line 236, in handle_request
    response = connection.handle_request(
        pool_request.request
    )
  File "C:\Users\grace\OneDrive\atom-bot\venv\Lib\site-packages\httpcore\_sync\connection.py", line 101, in handle_request
    raise exc
  File "C:\Users\grace\OneDrive\atom-bot\venv\Lib\site-packages\httpcore\_sync\connection.py", line 78, in handle_request
    stream = self._connect(request)
  File "C:\Users\grace\OneDrive\atom-bot\venv\Lib\site-packages\httpcore\_sync\connection.py", line 124, in _connect
    stream = self._network_backend.connect_tcp(**kwargs)
  File "C:\Users\grace\OneDrive\atom-bot\venv\Lib\site-packages\httpcore\_backends\sync.py", line 207, in connect_tcp
    with map_exceptions(exc_map):
         ~~~~~~~~~~~~~~^^^^^^^^^
  File "C:\Users\grace\AppData\Local\Programs\Python\Python313\Lib\contextlib.py", line 162, in __exit__
    self.gen.throw(value)
    ~~~~~~~~~~~~~~^^^^^^^
  File "C:\Users\grace\OneDrive\atom-bot\venv\Lib\site-packages\httpcore\_exceptions.py", line 14, in map_exceptions
    raise to_exc(exc) from exc
httpcore.ConnectTimeout: [WinError 10060] A connection attempt failed because the connected party did not properly respond after a period of time, or established connection failed because connected host has failed to respond

The above exception was the direct cause of the following exception:

Traceback (most recent call last):
  File "C:\Users\grace\OneDrive\atom-bot\venv\Lib\site-packages\discord\client.py", line 481, in _run_event
    await coro(*args, **kwargs)
  File "C:\Users\grace\OneDrive\atom-bot\cogs\chat.py", line 28, in on_message
    response = query_ollama(message.content)
  File "C:\Users\grace\OneDrive\atom-bot\ollama_client.py", line 66, in query_ollama
    response = ollama_client.chat(
        model=OLLAMA_MODEL,
    ...<11 lines>...
        }
    )
  File "C:\Users\grace\OneDrive\atom-bot\venv\Lib\site-packages\ollama\_client.py", line 342, in chat
    return self._request(
           ~~~~~~~~~~~~~^
      ChatResponse,
      ^^^^^^^^^^^^^
    ...<12 lines>...
      stream=stream,
      ^^^^^^^^^^^^^^
    )
    ^
  File "C:\Users\grace\OneDrive\atom-bot\venv\Lib\site-packages\ollama\_client.py", line 180, in _request
    return cls(**self._request_raw(*args, **kwargs).json())
                 ~~~~~~~~~~~~~~~~~^^^^^^^^^^^^^^^^^
  File "C:\Users\grace\OneDrive\atom-bot\venv\Lib\site-packages\ollama\_client.py", line 120, in _request_raw
    r = self._client.request(*args, **kwargs)
  File "C:\Users\grace\OneDrive\atom-bot\venv\Lib\site-packages\httpx\_client.py", line 825, in request
    return self.send(request, auth=auth, follow_redirects=follow_redirects)
           ~~~~~~~~~^^^^^^^^^^^^^^^^^^^^^^^^^^^^^^^^^^^^^^^^^^^^^^^^^^^^^^^
  File "C:\Users\grace\OneDrive\atom-bot\venv\Lib\site-packages\httpx\_client.py", line 914, in send
    response = self._send_handling_auth(
        request,
    ...<2 lines>...
        history=[],
    )
  File "C:\Users\grace\OneDrive\atom-bot\venv\Lib\site-packages\httpx\_client.py", line 942, in _send_handling_auth
    response = self._send_handling_redirects(
        request,
        follow_redirects=follow_redirects,
        history=history,
    )
  File "C:\Users\grace\OneDrive\atom-bot\venv\Lib\site-packages\httpx\_client.py", line 979, in _send_handling_redirects
    response = self._send_single_request(request)
  File "C:\Users\grace\OneDrive\atom-bot\venv\Lib\site-packages\httpx\_client.py", line 1014, in _send_single_request
    response = transport.handle_request(request)
  File "C:\Users\grace\OneDrive\atom-bot\venv\Lib\site-packages\httpx\_transports\default.py", line 249, in handle_request
    with map_httpcore_exceptions():
         ~~~~~~~~~~~~~~~~~~~~~~~^^
  File "C:\Users\grace\AppData\Local\Programs\Python\Python313\Lib\contextlib.py", line 162, in __exit__
    self.gen.throw(value)
    ~~~~~~~~~~~~~~^^^^^^^
  File "C:\Users\grace\OneDrive\atom-bot\venv\Lib\site-packages\httpx\_transports\default.py", line 118, in map_httpcore_exceptions
    raise mapped_exc(message) from exc
httpx.ConnectTimeout: [WinError 10060] A connection attempt failed because the connected party did not properly respond after a period of time, or established connection failed because connected host has failed to respond
ERROR:discord.ext.commands.bot:Ignoring exception in command settimezone
Traceback (most recent call last):
  File "C:\Users\grace\OneDrive\atom-bot\venv\Lib\site-packages\discord\ext\commands\bot.py", line 1366, in invoke
    await ctx.command.invoke(ctx)
  File "C:\Users\grace\OneDrive\atom-bot\venv\Lib\site-packages\discord\ext\commands\core.py", line 1021, in invoke
    await self.prepare(ctx)
  File "C:\Users\grace\OneDrive\atom-bot\venv\Lib\site-packages\discord\ext\commands\core.py", line 938, in prepare
    await self._parse_arguments(ctx)
  File "C:\Users\grace\OneDrive\atom-bot\venv\Lib\site-packages\discord\ext\commands\core.py", line 845, in _parse_arguments
    transformed = await self.transform(ctx, param, attachments)
                  ^^^^^^^^^^^^^^^^^^^^^^^^^^^^^^^^^^^^^^^^^^^^^
  File "C:\Users\grace\OneDrive\atom-bot\venv\Lib\site-packages\discord\ext\commands\core.py", line 697, in transform
    raise MissingRequiredArgument(param)
discord.ext.commands.errors.MissingRequiredArgument: tz is a required argument that is missing.
ERROR:discord.ext.commands.bot:Ignoring exception in command None
discord.ext.commands.errors.CommandNotFound: Command "checkcalendaar" is not found
WARNING:discord.gateway:Shard ID None heartbeat blocked for more than 10 seconds.
Loop thread traceback (most recent call last):
  File "C:\Users\grace\OneDrive\atom-bot\bot.py", line 47, in <module>
    bot.run(DISCORD_TOKEN)
  File "C:\Users\grace\OneDrive\atom-bot\venv\Lib\site-packages\discord\client.py", line 906, in run
    asyncio.run(runner())
  File "C:\Users\grace\AppData\Local\Programs\Python\Python313\Lib\asyncio\runners.py", line 194, in run
    return runner.run(main)
  File "C:\Users\grace\AppData\Local\Programs\Python\Python313\Lib\asyncio\runners.py", line 118, in run
    return self._loop.run_until_complete(task)
  File "C:\Users\grace\AppData\Local\Programs\Python\Python313\Lib\asyncio\base_events.py", line 707, in run_until_complete
    self.run_forever()
  File "C:\Users\grace\AppData\Local\Programs\Python\Python313\Lib\asyncio\base_events.py", line 678, in run_forever
    self._run_once()
  File "C:\Users\grace\AppData\Local\Programs\Python\Python313\Lib\asyncio\base_events.py", line 2033, in _run_once
    handle._run()
  File "C:\Users\grace\AppData\Local\Programs\Python\Python313\Lib\asyncio\events.py", line 89, in _run
    self._context.run(self._callback, *self._args)
  File "C:\Users\grace\OneDrive\atom-bot\venv\Lib\site-packages\discord\client.py", line 481, in _run_event
    await coro(*args, **kwargs)
  File "C:\Users\grace\OneDrive\atom-bot\cogs\chat.py", line 28, in on_message
    response = query_ollama(message.content)
  File "C:\Users\grace\OneDrive\atom-bot\ollama_client.py", line 66, in query_ollama
    response = ollama_client.chat(
  File "C:\Users\grace\OneDrive\atom-bot\venv\Lib\site-packages\ollama\_client.py", line 342, in chat
    return self._request(
  File "C:\Users\grace\OneDrive\atom-bot\venv\Lib\site-packages\ollama\_client.py", line 180, in _request
    return cls(**self._request_raw(*args, **kwargs).json())
  File "C:\Users\grace\OneDrive\atom-bot\venv\Lib\site-packages\ollama\_client.py", line 120, in _request_raw
    r = self._client.request(*args, **kwargs)
  File "C:\Users\grace\OneDrive\atom-bot\venv\Lib\site-packages\httpx\_client.py", line 825, in request
    return self.send(request, auth=auth, follow_redirects=follow_redirects)
  File "C:\Users\grace\OneDrive\atom-bot\venv\Lib\site-packages\httpx\_client.py", line 914, in send
    response = self._send_handling_auth(
  File "C:\Users\grace\OneDrive\atom-bot\venv\Lib\site-packages\httpx\_client.py", line 942, in _send_handling_auth
    response = self._send_handling_redirects(
  File "C:\Users\grace\OneDrive\atom-bot\venv\Lib\site-packages\httpx\_client.py", line 979, in _send_handling_redirects
    response = self._send_single_request(request)
  File "C:\Users\grace\OneDrive\atom-bot\venv\Lib\site-packages\httpx\_client.py", line 1014, in _send_single_request
    response = transport.handle_request(request)
  File "C:\Users\grace\OneDrive\atom-bot\venv\Lib\site-packages\httpx\_transports\default.py", line 250, in handle_request
    resp = self._pool.handle_request(req)
  File "C:\Users\grace\OneDrive\atom-bot\venv\Lib\site-packages\httpcore\_sync\connection_pool.py", line 236, in handle_request
    response = connection.handle_request(
  File "C:\Users\grace\OneDrive\atom-bot\venv\Lib\site-packages\httpcore\_sync\connection.py", line 78, in handle_request
    stream = self._connect(request)
  File "C:\Users\grace\OneDrive\atom-bot\venv\Lib\site-packages\httpcore\_sync\connection.py", line 124, in _connect
    stream = self._network_backend.connect_tcp(**kwargs)
  File "C:\Users\grace\OneDrive\atom-bot\venv\Lib\site-packages\httpcore\_backends\sync.py", line 208, in connect_tcp
    sock = socket.create_connection(
  File "C:\Users\grace\AppData\Local\Programs\Python\Python313\Lib\socket.py", line 849, in create_connection
    sock.connect(sa)

ERROR:discord.client:Ignoring exception in on_message
Traceback (most recent call last):
  File "C:\Users\grace\OneDrive\atom-bot\venv\Lib\site-packages\httpx\_transports\default.py", line 101, in map_httpcore_exceptions
    yield
  File "C:\Users\grace\OneDrive\atom-bot\venv\Lib\site-packages\httpx\_transports\default.py", line 250, in handle_request
    resp = self._pool.handle_request(req)
  File "C:\Users\grace\OneDrive\atom-bot\venv\Lib\site-packages\httpcore\_sync\connection_pool.py", line 256, in handle_request
    raise exc from None
  File "C:\Users\grace\OneDrive\atom-bot\venv\Lib\site-packages\httpcore\_sync\connection_pool.py", line 236, in handle_request
    response = connection.handle_request(
        pool_request.request
    )
  File "C:\Users\grace\OneDrive\atom-bot\venv\Lib\site-packages\httpcore\_sync\connection.py", line 101, in handle_request
    raise exc
  File "C:\Users\grace\OneDrive\atom-bot\venv\Lib\site-packages\httpcore\_sync\connection.py", line 78, in handle_request
    stream = self._connect(request)
  File "C:\Users\grace\OneDrive\atom-bot\venv\Lib\site-packages\httpcore\_sync\connection.py", line 124, in _connect
    stream = self._network_backend.connect_tcp(**kwargs)
  File "C:\Users\grace\OneDrive\atom-bot\venv\Lib\site-packages\httpcore\_backends\sync.py", line 207, in connect_tcp
    with map_exceptions(exc_map):
         ~~~~~~~~~~~~~~^^^^^^^^^
  File "C:\Users\grace\AppData\Local\Programs\Python\Python313\Lib\contextlib.py", line 162, in __exit__
    self.gen.throw(value)
    ~~~~~~~~~~~~~~^^^^^^^
  File "C:\Users\grace\OneDrive\atom-bot\venv\Lib\site-packages\httpcore\_exceptions.py", line 14, in map_exceptions
    raise to_exc(exc) from exc
httpcore.ConnectTimeout: [WinError 10060] A connection attempt failed because the connected party did not properly respond after a period of time, or established connection failed because connected host has failed to respond

The above exception was the direct cause of the following exception:

Traceback (most recent call last):
  File "C:\Users\grace\OneDrive\atom-bot\venv\Lib\site-packages\discord\client.py", line 481, in _run_event
    await coro(*args, **kwargs)
  File "C:\Users\grace\OneDrive\atom-bot\cogs\chat.py", line 28, in on_message
    response = query_ollama(message.content)
  File "C:\Users\grace\OneDrive\atom-bot\ollama_client.py", line 66, in query_ollama
    response = ollama_client.chat(
        model=OLLAMA_MODEL,
    ...<11 lines>...
        }
    )
  File "C:\Users\grace\OneDrive\atom-bot\venv\Lib\site-packages\ollama\_client.py", line 342, in chat
    return self._request(
           ~~~~~~~~~~~~~^
      ChatResponse,
      ^^^^^^^^^^^^^
    ...<12 lines>...
      stream=stream,
      ^^^^^^^^^^^^^^
    )
    ^
  File "C:\Users\grace\OneDrive\atom-bot\venv\Lib\site-packages\ollama\_client.py", line 180, in _request
    return cls(**self._request_raw(*args, **kwargs).json())
                 ~~~~~~~~~~~~~~~~~^^^^^^^^^^^^^^^^^
  File "C:\Users\grace\OneDrive\atom-bot\venv\Lib\site-packages\ollama\_client.py", line 120, in _request_raw
    r = self._client.request(*args, **kwargs)
  File "C:\Users\grace\OneDrive\atom-bot\venv\Lib\site-packages\httpx\_client.py", line 825, in request
    return self.send(request, auth=auth, follow_redirects=follow_redirects)
           ~~~~~~~~~^^^^^^^^^^^^^^^^^^^^^^^^^^^^^^^^^^^^^^^^^^^^^^^^^^^^^^^
  File "C:\Users\grace\OneDrive\atom-bot\venv\Lib\site-packages\httpx\_client.py", line 914, in send
    response = self._send_handling_auth(
        request,
    ...<2 lines>...
        history=[],
    )
  File "C:\Users\grace\OneDrive\atom-bot\venv\Lib\site-packages\httpx\_client.py", line 942, in _send_handling_auth
    response = self._send_handling_redirects(
        request,
        follow_redirects=follow_redirects,
        history=history,
    )
  File "C:\Users\grace\OneDrive\atom-bot\venv\Lib\site-packages\httpx\_client.py", line 979, in _send_handling_redirects
    response = self._send_single_request(request)
  File "C:\Users\grace\OneDrive\atom-bot\venv\Lib\site-packages\httpx\_client.py", line 1014, in _send_single_request
    response = transport.handle_request(request)
  File "C:\Users\grace\OneDrive\atom-bot\venv\Lib\site-packages\httpx\_transports\default.py", line 249, in handle_request
    with map_httpcore_exceptions():
         ~~~~~~~~~~~~~~~~~~~~~~~^^
  File "C:\Users\grace\AppData\Local\Programs\Python\Python313\Lib\contextlib.py", line 162, in __exit__
    self.gen.throw(value)
    ~~~~~~~~~~~~~~^^^^^^^
  File "C:\Users\grace\OneDrive\atom-bot\venv\Lib\site-packages\httpx\_transports\default.py", line 118, in map_httpcore_exceptions
    raise mapped_exc(message) from exc
httpx.ConnectTimeout: [WinError 10060] A connection attempt failed because the connected party did not properly respond after a period of time, or established connection failed because connected host has failed to respond
ERROR:discord.client:Attempting a reconnect in 1.43s
Traceback (most recent call last):
  File "C:\Users\grace\OneDrive\atom-bot\venv\Lib\site-packages\discord\client.py", line 704, in connect
    await self.ws.poll_event()
  File "C:\Users\grace\OneDrive\atom-bot\venv\Lib\site-packages\discord\gateway.py", line 627, in poll_event
    await self.received_message(msg.data)
  File "C:\Users\grace\OneDrive\atom-bot\venv\Lib\site-packages\discord\gateway.py", line 532, in received_message
    await self.send_as_json(beat)
  File "C:\Users\grace\OneDrive\atom-bot\venv\Lib\site-packages\discord\gateway.py", line 663, in send_as_json
    await self.send(utils._to_json(data))
  File "C:\Users\grace\OneDrive\atom-bot\venv\Lib\site-packages\discord\gateway.py", line 659, in send
    await self.socket.send_str(data)
  File "C:\Users\grace\OneDrive\atom-bot\venv\Lib\site-packages\aiohttp\client_ws.py", line 245, in send_str
    await self._writer.send_frame(
        data.encode("utf-8"), WSMsgType.TEXT, compress=compress
    )
  File "C:\Users\grace\OneDrive\atom-bot\venv\Lib\site-packages\aiohttp\_websocket\writer.py", line 126, in send_frame
    raise ClientConnectionResetError("Cannot write to closing transport")
aiohttp.client_exceptions.ClientConnectionResetError: Cannot write to closing transport
INFO:discord.gateway:Shard ID None has successfully RESUMED session 7114d9b409374c10aa4ec9ecd348660d.
